---
title: Context Managers
weight: 10
date: 2025-09-24
---


Ever forgotten to close a file after you're done with it? Or spent ages debugging a database connection that wouldn't close? We've all been there. It's a common struggle for programmers, but Python offers an exquisite solution to this very problem: the **`with` statement**. In this article, we'll delve into this powerful feature, exploring not only how to use it but also why it's essential for writing clean, robust, and reliable code.
## The Problem: The Perils of Unmanaged Resources

Before we introduce our hero, the 'with' statement, let's examine the problem it was designed to address. Imagine you're writing a script to read from a file. A common, straightforward way to do this might look like this:



```Python
file = open('my_data.txt', 'r')
data = file.read()
print(data)

# You remember to close it
file.close() 
```

This code seems harmless enough. But what happens if something goes wrong in the middle?



```Python
file = open('my_data.txt', 'r')
data = file.read()
# What if an error happens right here?
result = 10 / 0  # A ZeroDivisionError occurs!
file.close()  # This line is never reached.
```

In the example above, the `ZeroDivisionError` halts the program abruptly. The `file.close()` line is **never executed**, leaving the file resource open. While this might seem like a minor issue for a single script, in a larger application—especially one that handles many files or database connections—this can lead to serious problems, such as resource leaks, where the program's resources are slowly depleted, eventually causing it to crash.

This is the messy and error-prone world that developers navigated before the advent of context managers. It required a lot of manual handling and boilerplate code to ensure that every single resource was closed correctly, regardless of the circumstances.

## The Solution: Enter the `with` Statement

Now, let's rewrite that problematic code using Python's **`with` statement**. This simple keyword not only makes our code cleaner but also ensures it is safe. It’s like a promise: "No matter what happens, I will handle the cleanup."

```Python
try:
    with open('my_data.txt', 'r') as file:
        data = file.read()
        print(data)
        # What if an error happens here?
        result = 10 / 0  # Still a ZeroDivisionError!
except ZeroDivisionError:
    print("Oops, you can't divide by zero!")
```

Even though a `ZeroDivisionError` still occurs, the `with` statement ensures that the `file` is **automatically and properly closed** before the `except` block is executed. You don't have to remember to call `file.close()` yourself. The `with` statement handles the entire process, making your code more **robust** and **reliable**.

This is the power of a **context manager**. It wraps around a block of code, setting up a context for it to run in (`__enter__`) and then tearing it down afterward (`__exit__`), regardless of whether the code runs to completion or raises an error.

## Under the Hood: The What, Why, How, When, and Where

So, how does the `with` statement work its magic? At its core, it's all about a simple protocol. Any object can be a **context manager** as long as it has two special methods: `__enter__` and `__exit__`.

**The "What": The `__enter__` and `__exit__` Methods**
    
The `with` statement works like a temporary wrapper. When the line `with some_object as my_alias:` is executed, Python does the following behind the scenes:
1. It calls `some_object.__enter__()`.
2. The value returned by `__enter__` is assigned to `my_alias`.
3. The code block inside the `with` statement is executed.
4. Finally, no matter what happens (even if an error occurs!), it calls `some_object.__exit__()`.

This simple mechanism ensures that the cleanup code in `__exit__` is always executed. It's the ultimate "I promise to clean up after myself" guarantee.

**The "Why": Beyond Just Files**

The reason this is so powerful is that the concept of "resource management" goes far beyond just files. It applies to anything that needs a setup and a teardown process. Think about it:

- **Databases:** You `__enter__` to open a database connection and `__exit__` to ensure it's closed.	
- **Threading:** You `__enter__` to acquire a lock and `__exit__` to release it, preventing deadlocks.
- **Networking:** You `__enter__` to open a socket and `__exit__` to close it.

**The "How": An `__exit__` with a Purpose**
    
The `__exit__` method is actually quite clever. It takes three arguments: `exc_type`, `exc_val`, and `traceback`. These arguments are `None` if the `with` block ran without an error. But if an exception occurred, they contain the details of that error. This gives your context manager the power to handle or suppress exceptions gracefully, which we'll explore in a more advanced section.

## Context Managers in Standard Library

You've actually already seen the most famous context manager in Python: the built-in `open()` function. But countless others solve different problems. Let's examine a few examples that intermediate programmers are likely to encounter.
### File Handling: The `open()` Function

This is the one that started it all. When you use `with open(...)`, you're getting an object that handles all the setup and cleanup for you.

**Code Walkthrough:**

```Python
# A simple example
with open('data.txt', 'w') as f:
    f.write('Hello, World!')
```

1. `open('data.txt', 'w')` is called, and the file is opened for writing. This is the **`__enter__`** part of the process.
2. The file object is assigned to the variable `f` thanks to the `as` keyword.
3. The code inside the `with` block, `f.write('Hello, World!')`, is executed.
4. When the block is exited, Python automatically calls the file object's **`__exit__`** method, which flushes any buffered data and closes the file, guaranteeing that the changes are saved and the resource is released.

### Threading: The `threading.Lock`

In multithreaded programs, a common issue is race conditions where multiple threads attempt to access the same resource simultaneously. The `threading.Lock` object acts as a context manager to prevent this.



```Python
import threading

lock = threading.Lock()
count = 0

def increment():
    global count
    with lock:
        # This code block is a "critical section"
        # Only one thread can be here at a time.
        count += 1

# ... run threads that call increment()
```

**Code Walkthrough:**

1. When the `with lock:` line is executed, the lock's **`__enter__`** method is called. This method **acquires the lock**, making the current thread the only one that can proceed. Any other thread that tries to enter this block will be forced to wait.
2. The code inside the block (`count += 1`) runs safely.
3. Once the block is exited, the lock's **`__exit__`** method is called, which **releases the lock**. This allows another waiting thread to acquire it and continue.

Even if the code inside the `with` block throws an exception, the lock will still get released.
### Redirecting Standard Output with `contextlib`

The `contextlib` module is a goldmine for context manager utilities. One very cool example is `redirect_stdout`, which allows you to temporarily redirect print statements to a different location, such as a file or a string.


```Python
from contextlib import redirect_stdout
import io

f = io.StringIO()

with redirect_stdout(f):
    print('This will not be printed to the console!')
    print('Instead, it will be captured in the StringIO object.')

# The `with` block has ended, and our standard output is back to normal.
s = f.getvalue()
print('This is the captured text:')
print(s)
```

**Code Walkthrough:**

1. `redirect_stdout(f)`'s **`__enter__`** method saves the current `sys.stdout` and temporarily replaces it with our `io.StringIO` object `f`.
2. The `print` statements inside the block write their output to the `f` object instead of the console.
3. When the block ends, `redirect_stdout`'s **`__exit__`** method is called, which restores the original `sys.stdout`. The standard output is now back to where it was, and the `print` statement at the end of the code works as expected.
### Networking: The `socket` Module

When working with network connections, ensure that sockets are properly closed to free up system resources. Python's `socket` objects can also be used as context managers.

```Python
import socket

# This is a simplified example
with socket.socket(socket.AF_INET, socket.SOCK_STREAM) as s:
    # A simplified example of connecting
    s.connect(('www.python.org', 80))
    print("Socket connected successfully!")
    # The socket is automatically closed when the 'with' block is exited
```

**Code Walkthrough:**

1. The `with socket.socket(...) as s:` line calls the socket object's `__enter__` method. This returns the socket object itself, which is then assigned to `s`.
2. The code inside the block connects to the host.
3. When the `with` block is exited (successfully or with an error), the socket's `__exit__` method is called, which handles the necessary cleanup and closes the connection. This prevents a "dangling" socket that could keep a port busy or waste system resources.

### Decimal Precision: `decimal.localcontext`

Sometimes, you need to temporarily change a global setting for a specific block of code. The `decimal.localcontext` context manager is perfect for this. It allows you to adjust the precision of decimal calculations temporarily.

```Python
import decimal

with decimal.localcontext() as ctx:
    ctx.prec = 4  # Temporarily set precision to 4
    x = decimal.Decimal('1.23456789')
    print(f"Inside with block (precision 4): {x}") # Output: 1.235

# The precision is automatically reset to the original value here
x = decimal.Decimal('1.23456789')
print(f"Outside with block (original precision): {x}") # Output: 1.23456789
```

**Code Walkthrough:**

1. `decimal.localcontext()`'s `__enter__` method creates a new, temporary context and makes it active.
2. Inside the `with` block, we can modify the `ctx.prec` attribute, and this change only affects the code within this block.
3. When the block is exited, `__exit__` automatically restores the global `decimal` context to its original state. This is a brilliant use of a context manager for "scoped" state changes.

### Testing: `unittest.mock.patch`

In software testing, you often need to temporarily replace an object with a "mock" version for a test. The `unittest.mock.patch` context manager makes this incredibly easy and reliable.

```Python
from unittest.mock import patch
import os

# Imagine we have a function that checks for a file
def check_if_exists(filepath):
    return os.path.exists(filepath)

# Now let's test it without creating a real file
with patch('os.path.exists') as mock_exists:
    mock_exists.return_value = True
    assert check_if_exists('my_fake_file.txt') == True

# The original os.path.exists is restored automatically
assert check_if_exists('my_fake_file.txt') == False
```

**Code Walkthrough:**

1. `patch('os.path.exists')`'s `__enter__` method replaces the real `os.path.exists` function with a `MagicMock` object and assigns it to `mock_exists`.
2. We can then set the mock's behavior inside the `with` block (`mock_exists.return_value = True`).
3. When the `with` block is exited, the `__exit__` method **automatically restores the original `os.path.exists` function**, ensuring our test doesn't have unintended side effects on other parts of our program. This is a crucial feature for writing isolated and repeatable tests.
### Temporary Directories: `tempfile.TemporaryDirectory`

When you need a temporary space to create files and subdirectories for a task, you want to be absolutely sure that everything gets cleaned up afterward. The `tempfile.TemporaryDirectory` context manager is perfect for this. It creates a temporary directory and automatically deletes it and all its contents when the `with` block is exited.

```Python
import tempfile
import os

with tempfile.TemporaryDirectory() as tmpdir:
    # We are inside the temporary directory
    print(f'Created temporary directory: {tmpdir}')
    
    # Create a file inside it
    temp_file_path = os.path.join(tmpdir, 'my_temp_file.txt')
    with open(temp_file_path, 'w') as f:
        f.write('This file will be gone soon!')
    
    # You can still see the file here
    print(f'File exists: {os.path.exists(temp_file_path)}')

# The 'with' block is now exited, and the temporary directory is deleted.
print(f'Directory and file are gone: {os.path.exists(tmpdir)}')
```

**Code Walkthrough:**

1. `tempfile.TemporaryDirectory()`'s **`__enter__`** method creates a new, empty directory with a unique name and returns its path as a string.
2. The code inside the `with` block can use this directory for any temporary work.
3. When the block is exited, the **`__exit__`** method is called, which recursively deletes the directory and all of its contents. This is an incredibly safe way to handle temporary data.
### Re-entrant Locks: `threading.RLock`

You already saw `threading.Lock` used as a context manager, but what if a function that already holds a lock needs to call another function that also tries to acquire the same lock? A standard `Lock` would cause a **deadlock**, but a **re-entrant lock** (`RLock`) solves this problem.

```Python
import threading

# A re-entrant lock allows the same thread to acquire it multiple times.
r_lock = threading.RLock()

def step_one():
    with r_lock:
        print("Inside step one, acquiring lock.")
        step_two() # Calls another function that needs the same lock

def step_two():
    with r_lock:
        print("Inside step two, acquiring lock again.")
        # This works because the lock is re-entrant.

# The lock is released only when the outermost 'with' block is exited.
step_one()
```

**Code Walkthrough:**

1. The first `with r_lock:` call in `step_one` acquires the lock, and an internal counter is set to 1.
2. Inside this block, `step_two` is called, and it tries to acquire the lock again.
3. Because it's an `RLock`, the same thread can acquire it, and the internal counter simply increments to 2. No deadlock occurs.
4. The lock is not truly released until the **`__exit__`** method is called for both `with` blocks, decrementing the counter back to 0.

### Closing: `contextlib.closing`

Sometimes you have a third-party object that has a `close()` method but isn't designed to be a context manager. Instead of writing your own class, you can use `contextlib.closing` to make it behave like one!

```Python
from contextlib import closing
from urllib.request import urlopen

# The urlopen object has a close() method, but no __enter__/__exit__
with closing(urlopen('https://www.python.org')) as page:
    for line in page:
        print(line)

# The 'page' object is guaranteed to be closed here.
```

**Code Walkthrough:**

1. `closing(urlopen(...))` takes any object that has a `close()` method.
2. Its `__enter__` method simply returns the object itself.
3. Its `__exit__` method **guarantees** that `obj.close()` is called, no matter what happens inside the `with` block. This is a brilliant way to wrap non-compliant objects and add a layer of safety without writing any extra boilerplate code.


These examples clearly demonstrate that context managers are more than just file management; they represent a pattern for consistently and robustly managing a wide range of resources.

### Simulating `contextlib.closing`

The `closing` function is actually a class that implements the context manager protocol. It’s designed to be a thin wrapper around another object.

The goal is to take an object that has a `.close()` method but isn't a context manager itself, and make it behave like one. The key is that `closing` doesn't know what kind of object it's wrapping; it just knows that it needs to call a `.close()` method when it's done.

We can create a simple class to replicate this behavior. Let's call it `SimpleClosing`.

```Python
class SimpleClosing:
    def __init__(self, thing):
        # The 'thing' is the object we're wrapping, e.g., a network connection.
        self.thing = thing

    def __enter__(self):
        # The __enter__ method simply returns the object itself.
        # This is what gets assigned to the 'as' variable in the 'with' statement.
        return self.thing

    def __exit__(self, exc_type, exc_val, exc_tb):
        # The __exit__ method is the cleanup crew.
        # It's called whether the block runs successfully or with an error.
        # Its only job is to call the close() method on our wrapped object.
        self.thing.close()

# Let's see it in action with a dummy object
class MyResource:
    def close(self):
        print("MyResource is now closed.")

with SimpleClosing(MyResource()) as my_resource:
    print("Inside the 'with' block.")
    # The with block is running, but the cleanup hasn't happened yet.

print("Outside the 'with' block.")
```

**Walkthrough of the `SimpleClosing` code:**

1. **`__init__(self, thing)`**: The constructor takes one argument, `thing`, which is the object we want to manage (e.g., a file, socket, or database connection). It simply stores this object as an instance variable.
2. **`__enter__(self)`**: When the `with SimpleClosing(...)` statement is executed, Python calls this method. Its responsibility is to return the object that will be used inside the `with` block. In this case, we just return `self.thing`, the resource we are managing. This is what gets assigned to the variable `my_resource` in our example.
3. **`__exit__(self, exc_type, exc_val, exc_tb)`**: When the `with` block is exited for any reason (normal completion, an exception, or a `return` statement), Python calls this method. The `exc_type`, `exc_val`, and `exc_tb` arguments are used for advanced exception handling, which we won't use in this simple example. The crucial part is that this method calls `self.thing.close()`, ensuring that our resource is cleaned up regardless of the circumstances.

This simple class effectively turns any object with a `close()` method into a fully compliant context manager, proving that the `with` statement is just a clever bit of syntactic sugar built on a straightforward protocol.
